Workbook

Sheet Judicatory Coverage WI
A1: Contact | B1: Judicary//Counties--> | C1: ALL | D1: Adams | E1: Ashland | F1: Barron | G1: Bayfield | H1: Brown | I1: Buffalo | J1: Burnett | K1: Calumet | L1: Chippewa | M1: Clark | N1: Crawford | O1: Columbia | P1: Dane | Q1: Dodge | R1: Door | S1: Douglas | T1: Dunn | U1: Eau Claire | V1: Florence | W1: Fond du Lac | X1: Forest | Y1: Grant | Z1: Green | AA1: Green Lake | AB1: Iowa | AC1: Iron | AD1: Jackson | AE1: Jefferson | AF1: Juneau | AG1: Kenosha | AH1: Kewaunee | AI1: La Crosse | AJ1: Lafayette | AK1: Langlade | AL1: Lincoln | AM1: Manitowoc | AN1: Marathon | AO1: Marinette | AP1: Marquette | AQ1: Menominee | AR1: Milwaukee | AS1: Monroe | AT1: Oconto | AU1: Oneida | AV1: Outagamie | AW1: Ozaukee | AX1: Pepin | AY1: Pierce | AZ1: Polk | BA1: Portage | BB1: Price | BC1: Racine | BD1: Richland | BE1: Rock | BF1: Rusk | BG1: Sauk | BH1: Sawyer | BI1: Shawano | BJ1: Sheboygan | BK1: St. Croix | BL1: Taylor | BM1: Trempealeau | BN1: Vernon | BO1: Vilas | BP1: Walworth | BQ1: Washburn | BR1: Washington | BS1: Waukesha | BT1: Waupaca | BU1: Waushara | BV1: Winnebago | BW1: Wood | BX1: Counties Covered
A2: Presiding Elder James Miller | B2: African Methodist Episcopal Church, 4th District | C2: ALL | N2: x | O2: x | P2: x | Q2: x | Y2: x | Z2: x | AB2: x | AE2: x | AG2: x | AJ2: x | AR2: x | AW2: x | BC2: x | BD2: x | BE2: x | BG2: x | BJ2: x | BP2: x | BR2: x | BX2: =COUNTA(D2:BW2) -> 19
A3: Rev. Mindi Welton-Mitchell | B3: American Baptist Churches of Wisconsin | C3: ALL | N3: x | O3: x | P3: x | Q3: x | Y3: x | Z3: x | AB3: x | AE3: x | AG3: x | AJ3: x | AR3: x | AW3: x | BC3: x | BD3: x | BE3: x | BG3: x | BJ3: x | BP3: x | BR3: x | BX3: =COUNTA(D3:BW3) -> 19
A4: Father Yeprem Kelegian | B4: Armenian Orthodox Church, Eastern Diocese | C4: ALL | Z4: x | AR4: x | BC4: x | BX4: =COUNTA(D4:BW4) -> 3
A5: Rev. Eli Rolon-Jeong | B5: Christian Church (Disciples of Christ) in Illinois and Wisconsin | C5: ALL | AR5: x | BX5: =COUNTA(D5:BW5) -> 1
A6: Elder Tiggs Washington | B6: Christian Methodist Episcopal Church, Third Episcopal District | C6: ALL | AR6: x | BE6: x | BX6: =COUNTA(D6:BW6) -> 2
A7: Mr. Brett Seamons | B7: Church of Jesus Christ of Latter-Day Saints | C7: ALL
A8: Rev. Walt Wiltshek | B8: Church of the Brethren, Illinois and Wisconsin District | C8: ALL | P8: x | BX8: =COUNTA(D8:BW8) -> 1
A9: Bishop Darrell Hines, Sr. | B9: COGIC, Wisconsin First Jurisdiction | C9: PR | P9: x | Z9: x | AR9: x | BX9: =COUNTA(D9:BW9) -> 3
A10: Bishop CH McClelland | B10: COGIC, Wisconsin Northwest Jurisdiction | C10: PR | AR10: x | BX10: =COUNTA(D10:BW10) -> 1
A11: incomplete | B11: COGIC, Wisconsin Third Jurisdiction | C11: PR | BX11: =COUNTA(D11:BW11) -> 0
A12: Mr. Matt Davisdon | B12: Community of Christ Headwaters Mission Center | N12: x | P12: x | Y12: x | AR12: x | AX12: x | BE12: x
A13: Fr. Gergis (msn)/ Fr. Awadalla (mke) | B13: Coptic Orthodox Church | C13: ALL | P13: x | AR13: x | BX13: =COUNTA(D13:BW13) -> 2
A14: Rev. Mimi Maki | B14: Ecumenical Catholic Communion | BV14: x | BX14: =COUNTA(D14:BW14) -> 1
A15: Bishop Anne Edison Albright | B15: ELCA East-Central Synod | H15: x | K15: x | R15: x | W15: x | AA15: x | AH15: x | AK15: x | AL15: x | AM15: x | AN15: x | AP15: x | AQ15: x | AT15: x | BA15: x | BI15: x | BT15: x | BU15: x | BV15: x | BW15: x | BX15: =COUNTA(D15:BW15) -> 19
A16: Bishop Paul Erickson | B16: ELCA Greater Milwaukee Synod | AE16: x | AG16: x | AR16: x | AW16: x | BC16: x | BJ16: x | BR16: x | BS16: x | BX16: =COUNTA(D16:BW16) -> 8
A17: Bishop Felix Malpica | B17: ELCA LaCrosse Area Synod | D17: x | I17: x | N17: x | AG17: x | AI17: x | BM17: x | BN17: x | BX17: =COUNTA(D17:BW17) -> 7
A18: Bishop Katherine Finegan | B18: ELCA Northern Great Lakes Synod | BX18: =COUNTA(D18:BW18) -> 0
A19: Bishop Martin Halom | B19: ELCA Northwest Synod | E19: x | F19: x | G19: x | I19: x | J19: x | L19: x | M19: x | S19: x | T19: x | AD19: x | AN19: x | AX19: x | BB19: x | BF19: x | BK19: x | BL19: x | BM19: x | BR19: x | BW19: x | BX19: =COUNTA(D19:BW19) -> 19
A20: Bishop Joy Mortensen-Weibe | B20: ELCA South-Central Synod | O20: x | P20: x | Q20: x | Y20: x | Z20: x | AB20: x | AE20: x | AJ20: x | BD20: x | BE20: x | BG20: x | BP20: x | BX20: =COUNTA(D20:BW20) -> 12
A21: Father Cyprian Sas | B21: Greek Orthodox Church, Diocese of Chicago | N21: x | O21: x | P21: x | Q21: x | Y21: x | Z21: x | AB21: x | AE21: x | AG21: x | AJ21: x | AR21: x | AW21: x | BC21: x | BD21: x | BE21: x | BG21: x | BP21: x | BR21: x | BX21: =COUNTA(D21:BW21) -> 18
A22: Sr. Leader Adam Clausen | B22: Life Center Madison | P22: x | BX22: =COUNTA(D22:BW22) -> 1
A23: Rev. Valerie Showalter at MMC | B23: Mennonite Church USA, Central District Conference | C23: ALL | N23: x | O23: x | P23: x | Q23: x | Y23: x | Z23: x | AB23: x | AE23: x | AG23: x | AJ23: x | AR23: x | AW23: x | BC23: x | BD23: x | BE23: x | BG23: x | BJ23: x | BP23: x | BR23: x | BX23: =COUNTA(D23:BW23) -> 19
A24: Lay Led | B24: Metropolitan Community Churches | C24: ALL | Z24: x | AR24: x | AV24: x | BR24: x | BX24: =COUNTA(D24:BW24) -> 4
A25: Jason Andersen | B25: Moravian Church, Western District | C25: ALL | N25: x | O25: x | P25: x | Q25: x | Y25: x | Z25: x | AB25: x | AE25: x | AG25: x | AJ25: x | AR25: x | AW25: x | BC25: x | BD25: x | BE25: x | BG25: x | BJ25: x | BP25: x | BR25: x | BX25: =COUNTA(D25:BW25) -> 19
A26: Fr. Elijah Mueller | B26: Orthodox Church in America, Diocese of the Midwest | C26: ALL | N26: x | O26: x | P26: x | Q26: x | Y26: x | Z26: x | AB26: x | AE26: x | AG26: x | AJ26: x | AR26: x | AW26: x | BC26: x | BD26: x | BE26: x | BG26: x | BJ26: x | BP26: x | BR26: x | BX26: =COUNTA(D26:BW26) -> 19
A27: Rev. Jeff Japinga | B27: PC(USA), John Knox Presbytery | D27: x | I27: x | N27: x | O27: x | P27: x | Y27: x | Z27: x | AB27: x | AD27: x | AF27: x | AI27: x | AJ27: x | AP27: x | AS27: x | BD27: x | BG27: x | BM27: x | BN27: x | BX27: =COUNTA(D27:BW27) -> 18
A28: Rev. Christian Boyd | B28: PC(USA), Milwaukee Presbytery | Q28: x | AE28: x | AG28: x | AR28: x | AW28: x | BC28: x | BE28: x | BJ28: x | BP28: x | BR28: x | BS28: x | BX28: =COUNTA(D28:BW28) -> 11
A29: Rev. Devon Borden Reynolds | B29: PC(USA), Northern Waters Presbytery | E29: x | F29: x | G29: x | J29: x | L29: x | M29: x | S29: x | T29: x | U29: x | AC29: x | AX29: x | AY29: x | AZ29: x | BB29: x | BF29: x | BH29: x | BK29: x | BL29: x | BO29: x | BQ29: x | BX29: =COUNTA(D29:BW29) -> 20
A30: Rev. Dave Colby | B30: PC(USA), Winnebago Presbytery | H30: x | K30: x | R30: x | V30: x | W30: x | X30: x | AA30: x | AH30: x | AK30: x | AL30: x | AM30: x | AN30: x | AO30: x | AQ30: x | AT30: x | AU30: x | AV30: x | BA30: x | BI30: x | BT30: x | BU30: x | BV30: x | BW30: x | BX30: =COUNTA(D30:BW30) -> 23
A31: Archbishop Grob | B31: Roman Catholic Archdiocese of Milwaukee | Q31: x | W31: x | AG31: x | AR31: x | AW31: x | BC31: x | BJ31: x | BP31: x | BR31: x | BS31: x | BX31: =COUNTA(D31:BW31) -> 10
A32: Bishop Ricken | B32: Roman Catholic Diocese of Green Bay | H32: x | K32: x | R32: x | V32: x | X32: x | AH32: x | AK32: x | AM32: x | AO32: x | AQ32: x | AT32: x | AV32: x | BI32: x | BT32: x | BU32: x | BV32: x
A33: Bishop Battersby | B33: Roman Catholic Diocese of LaCrosse | D33: x | I33: x | L33: x | M33: x | N33: x | T33: x | U33: x | AD33: x | AF33: x | AI33: x | AN33: x | AS33: x | AX33: x | AY33: x | BA33: x | BD33: x | BM33: x | BN33: x | BW33: x
A34: Bishop Matthew Gunter | B34: The Episcopal Diocese of Wisconsin | C34: ALL | BX34: =COUNTA(D34:BW34) -> 0
A35: Rev. Jane Anderson | B35: UCC-WI, Eastern Region | H35: x | K35: x | Q35: x | R35: x | W35: x | AA35: x | AH35: x | AM35: x | AO35: x | AQ35: x | AR35: x | AT35: x | AV35: x | AW35: x | BI35: x | BJ35: x | BR35: x | BS35: x | BT35: x | BU35: x | BV35: x | BX35: =COUNTA(D35:BW35) -> 21
A36: vacant | B36: UCC-WI, Northern Region | E36: x | F36: x | G36: x | I36: x | J36: x | L36: x | M36: x | S36: x | T36: x | U36: x | V36: x | X36: x | AC36: x | AD36: x | AI36: x | AK36: x | AL36: x | AN36: x | AS36: x | AU36: x | AX36: x | AY36: x | AZ36: x | BA36: x | BB36: x | BF36: x | BH36: x | BK36: x | BL36: x | BM36: x | BO36: x | BQ36: x | BU36: x | BW36: x | BX36: =COUNTA(D36:BW36) -> 34
A37: Rev. Rachel Bauman | B37: UCC-WI, Southern Region | D37: x | N37: x | O37: x | P37: x | Q37: x | Y37: x | Z37: x | AB37: x | AE37: x | AF37: x | AG37: x | AJ37: x | AP37: x | BC37: x | BD37: x | BE37: x | BG37: x | BN37: x | BP37: x | BR37: x | BS37: x | BX37: =COUNTA(D37:BW37) -> 21
A38: Rev. M. Park Hunter | B38: UMC - WI, North East District | H38: x | K38: x | R38: x | V38: x | X38: x | AH38: x | AK38: x | AL38: x | AM38: x | AN38: x | AO38: x | AQ38: x | AT38: x | AU38: x | AV38: x | BA38: x | BI38: x | BJ38: x | BO38: x | BT38: x | BU38: x | BV38: x | BW38: x | BX38: =COUNTA(D38:BW38) -> 23
A39: Rev. PyungAhn "Peace" Kim | B39: UMC - WI, North West District | E39: x | F39: x | G39: x | I39: x | J39: x | L39: x | M39: x | S39: x | T39: x | U39: x | AC39: x | AD39: x | AI39: x | AX39: x | AY39: x | AZ39: x | BB39: x | BF39: x | BH39: x | BK39: x | BL39: x | BM39: x | BQ39: x | BX39: =COUNTA(D39:BW39) -> 23
A40: Rev. Amanda Stein | B40: UMC - WI, South East District | Q40: x | W40: x | AA40: x | AE40: x | AG40: x | AR40: x | AW40: x | BC40: x | BP40: x | BR40: x | BS40: x | BX40: =COUNTA(D40:BW40) -> 11
...

Sheet Data Collection
A1: Churches
A2: Counties | B2: Churches that are located in:
A3: Adams | B3: UCC, ELCA LaCrosse Area Synod
A4: Ashland | B4: EUCC, Evangelical Lutheran Church in America, Northwest Synod
A5: Barron | B5: UCC, Northern Waters Presbytery,ELCA Northwest Synod
A6: Bayfield | B6: UCC.ELCA Northwest Synod
A7: Brown | B7: RC Diocese of Green Bay, UCC, ELCA East-Central Synod, Winnebago Presbytery
A8: Buffalo | B8: ELCA LaCrosse , ELCA Northwest Synod
A9: Burnette | B9: UCC,ELCA Northwest Synod
A10: Calumet | B10: UCC, ELCA East-Central Synod
A11: Chippewa | B11: UCC, Northern Waters Presbytery, UCC, ELCA Northwest Synod
A12: Clark | B12: UCC, ELCA Northwest Synod
A13: Columbia | B13: UCC, Reformed Church in America, Synod of Mid-America
... A75: Wood | B75: UCC, ELCA Northwest Synod, ELCA East-Central Synod

Sheet Dashboard
B2: Wisconsin Judicatory Outreach Coordination Tool
B4: Leadership Guide's Guide: Identifying Overlapping Jurisdictions & Key Contacts
B6: =COUNTA(Data!A2:A61) -> 41 | D6: 72 | F6: 72 | H6: 346+
B7: Total Judicatories | D7: Counties with Overlap | F7: WI Counties Tracked | H7: Overlap Pairs
B9: Top 15 Counties by Judicatories Present | F9: Judicatory Summary — Auto-updates from DATA tab
B10: County | C10: # Judicatories | D10: Coverage Level | F10: Judicatory | G10: Contact | H10: ALL? | I10: Counties #
B11: Milwaukee | C11: 19 | D11: ★★★ Very High | F11: =Data!A36 -> UCC-WI, Northern Region | G11: =Data!B36 -> vacant | H11: =Data!C36 -> — | I11: =Data!D36 -> 34
B12: Dane | C12: 15 | D12: ★★★ Very High | F12: =Data!A30 -> PC(USA), Winnebago Presbytery | G12: =Data!B30 -> Rev. Dave Colby | H12: =Data!C30 -> — | I12: =Data!D30 -> 23
B13: Green | C13: 13 | D13: ★★★ High | F13: =Data!A38 -> UMC - WI, North East District | G13: =Data!B38 -> Rev. M. Park Hunter | H13: =Data!C38 -> — | I13: =Data!D38 -> 23
B14: Washington | C14: 13 | D14: ★★★ High | F14: =Data!A38 -> UMC - WI, North East District | G14: =Data!B38 -> Rev. M. Park Hunter | H14: =Data!C38 -> — | I14: =Data!D38 -> 23
B15: Crawford | C15: 12 | D15: ★★★ High | F15: =Data!A35 -> UCC-WI, Eastern Region | G15: =Data!B35 -> Rev. Jane Anderson | H15: =Data!C35 -> — | I15: =Data!D35 -> 21
B16: Dodge | C16: 12 | D16: ★★★ High | F16: =Data!A37 -> UCC-WI, Southern Region | G16: =Data!B37 -> Rev. Rachel Bauman | H16: =Data!C37 -> — | I16: =Data!D37 -> 21
B17: Racine | C17: 12 | D17: ★★★ High | F17: =Data!A29 -> PC(USA), Northern Waters Presbytery | G17: =Data!B29 -> Rev. Richard Blood | H17: =Data!C29 -> — | I17: =Data!D29 -> 20
B18: Rock | C18: 12 | D18: ★★★ High | F18: =Data!A2 -> African Methodist Episcopal Church, 4th District | G18: =Data!B2 -> Presiding Elder James Miller | H18: =Data!C2 -> ALL | I18: =Data!D2 -> 19
B19: Grant | C19: 11 | D19: ★★★ High | F19: =Data!A3 -> American Baptist Churches of Wisconsin | G19: =Data!B3 -> Rev. Mindi Welton-Mitchell | H19: =Data!C3 -> ALL | I19: =Data!D3 -> 19
B20: Kenosha | C20: 11 | D20: ★★★ High | F20: =Data!A15 -> ELCA East-Central Synod | G20: =Data!B15 -> Bishop Anne Edison Albright | H20: =Data!C15 -> — | I20: =Data!D15 -> 19
B21: Ozaukee | C21: 11 | D21: ★★★ High | F21: =Data!A19 -> ELCA Northwest Synod | G21: =Data!B19 -> Bishop Martin Halom | H21: =Data!C19 -> — | I21: =Data!D19 -> 19
B22: Richland | C22: 11 | D22: ★★★ High | F22: =Data!A23 -> Mennonite Church USA, Central District Conference | G22: =Data!B23 -> Rev. Valerie Showalter at MMC | H22: =Data!C23 -> — | I22: =Data!D23 -> 2
B23: Walworth | C23: 11 | D23: ★★★ High | F23: =Data!A25 -> Moravian Church, Western District | G23: =Data!B25 -> Jason Andersen | H23: =Data!C25 -> ALL | I23: =Data!D25 -> 19
B24: Columbia | C24: 10 | D24: ★★★ High | F24: =Data!A26 -> Orthodox Church in America, Diocese of the Midwest | G24: =Data!B26 -> Fr. Elijah Mueller | H24: =Data!C26 -> ALL | I24: =Data!D26 -> 19
B25: Iowa | C25: 10 | D25: ★★★ High | F25: =Data!A33 -> Roman Catholic Diocese of LaCrosse | G25: =Data!B33 -> Bishop Battersby | H25: =Data!C33 -> — | I25: =Data!D33 -> 19
B28: ℹ️ ALL = Statewide jurisdiction but communities only in marked counties | PR = Partial data

Sheet County Overlap Map
B2: County × Judicatory Coverage Matrix | Auto-updates when new members are added in DATA tab
B4: County | C4: # Serving | D4: =Data!A2 -> African Methodist Episcopal Church, 4th District | E4: =Data!A3 -> American Baptist Churches of Wisconsin | F4: =Data!A4 -> Armenian Orthodox Church, Eastern Diocese | G4: =Data!A5 -> Christian Church (Disciples of Christ) in Illinois and Wisconsin | H4: =Data!A6 -> Christian Methodist Episcopal Church, Third Episcopal District | I4: =Data!A7 -> Church of Jesus Christ of Latter-Day Saints | J4: =Data!A8 -> Church of the Brethren, Illinois and Wisconsin District | K4: =Data!A9 -> COGIC, Wisconsin First Jurisdiction | L4: =Data!A10 -> COGIC, Wisconsin Northwest Jurisdiction | M4: =Data!A11 -> COGIC, Wisconsin Third Jurisdiction | N4: =Data!A12 -> Community of Christ Headwaters Mission Center | O4: =Data!A13 -> Coptic Orthodox Church | P4: =Data!A14 -> Ecumenical Catholic Communion | Q4: =Data!A15 -> ELCA East-Central Synod | R4: =Data!A16 -> ELCA Greater Milwaukee Synod | S4: =Data!A17 -> ELCA LaCrosse Area Synod | T4: =Data!A18 -> ELCA Northern Great Lakes Synod | U4: =Data!A19 -> ELCA Northwest Synod | V4: =Data!A20 -> ELCA South-Central Synod | W4: =Data!A21 -> Greek Orthodox Church, Diocese of Chicago | X4: =Data!A22 -> Life Center Madison | Y4: =Data!A23 -> Mennonite Church USA, Central District Conference | Z4: =Data!A24 -> Metropolitan Community Churches | AA4: =Data!A25 -> Moravian Church, Western District | AB4: =Data!A26 -> Orthodox Church in America, Diocese of the Midwest | AC4: =Data!A27 -> PC(USA), John Knox Presbytery | AD4: =Data!A28 -> PC(USA), Milwaukee Presbytery | AE4: =Data!A29 -> PC(USA), Northern Waters Presbytery | AF4: =Data!A30 -> PC(USA), Winnebago Presbytery | AG4: =Data!A31 -> Roman Catholic Archdiocese of Milwaukee | AH4: =Data!A32 -> Roman Catholic Diocese of Green Bay | AI4: =Data!A33 -> Roman Catholic Diocese of LaCrosse | AJ4: =Data!A34 -> The Episcopal Diocese of Wisconsin | AK4: =Data!A35 -> UCC-WI, Eastern Region | AL4: =Data!A36 -> UCC-WI, Northern Region | AM4: =Data!A37 -> UCC-WI, Southern Region | AN4: =Data!A38 -> UMC - WI, North East District | AO4: =Data!A39 -> UMC - WI, North West District | AP4: =Data!A40 -> UMC - WI, South East District | AQ4: =Data!A41 -> UMC - WI, South West District | AR4: =Data!A42 -> UMC- Boo | AS4: =Data!A43 -> 0 | AT4: =Data!A44 -> 0 | AU4: =Data!A45 -> 0 | AV4: =Data!A46 -> 0 | AW4: =Data!A47 -> 0 | AX4: =Data!A48 -> 0 | AY4: =Data!A49 -> 0 | AZ4: =Data!A50 -> 0 | BA4: =Data!A51 -> 0 | BB4: =Data!A52 -> 0 | BC4: =Data!A53 -> 0 | BD4: =Data!A54 -> 0 | BE4: =Data!A55 -> 0 | BF4: =Data!A56 -> 0 | BG4: =Data!A57 -> 0 | BH4: =Data!A58 -> 0 | BI4: =Data!A59 -> 0 | BJ4: =Data!A60 -> 0 | BK4: =Data!A61 -> 0
B5: Adams | C5: =COUNTIF(Data!E2:E61,"x") -> 6 | D5: =IF(Data!E2="x","✓","") | E5: =IF(Data!E3="x","✓","") | F5: =IF(Data!E4="x","✓","") | G5: =IF(Data!E5="x","✓","") | H5: =IF(Data!E6="x","✓","") | I5: =IF(Data!E7="x","✓","") | J5: =IF(Data!E8="x","✓","") | K5: =IF(Data!E9="x","✓","") | L5: =IF(Data!E10="x","✓","") | M5: =IF(Data!E11="x","✓","") | N5: =IF(Data!E12="x","✓","") | O5: =IF(Data!E13="x","✓","") | P5: =IF(Data!E14="x","✓","") | Q5: =IF(Data!E15="x","✓","") | R5: =IF(Data!E16="x","✓","") | S5: =IF(Data!E17="x","✓","") -> ✓ | T5: =IF(Data!E18="x","✓","") | U5: =IF(Data!E19="x","✓","") | V5: =IF(Data!E20="x","✓","") | W5: =IF(Data!E21="x","✓","") | X5: =IF(Data!E22="x","✓","") | Y5: =IF(Data!E23="x","✓","") | Z5: =IF(Data!E24="x","✓","") | AA5: =IF(Data!E25="x","✓","") | AB5: =IF(Data!E26="x","✓","") | AC5: =IF(Data!E27="x","✓","") -> ✓ | AD5: =IF(Data!E28="x","✓","") | AE5: =IF(Data!E29="x","✓","") | AF5: =IF(Data!E30="x","✓","") | AG5: =IF(Data!E31="x","✓","") | AH5: =IF(Data!E32="x","✓","") | AI5: =IF(Data!E33="x","✓","") -> ✓ | AJ5: =IF(Data!E34="x","✓","") | AK5: =IF(Data!E35="x","✓","") | AL5: =IF(Data!E36="x","✓","") | AM5: =IF(Data!E37="x","✓","") -> ✓ | AN5: =IF(Data!E38="x","✓","") | AO5: =IF(Data!E39="x","✓","") | AP5: =IF(Data!E40="x","✓","") | AQ5: =IF(Data!E41="x","✓","") -> ✓ | AR5: =IF(Data!E42="x","✓","") -> ✓ | AS5: =IF(Data!E43="x","✓","") | AT5: =IF(Data!E44="x","✓","") | AU5: =IF(Data!E45="x","✓","") | AV5: =IF(Data!E46="x","✓","") | AW5: =IF(Data!E47="x","✓","") | AX5: =IF(Data!E48="x","✓","") | AY5: =IF(Data!E49="x","✓","") | AZ5: =IF(Data!E50="x","✓","") | BA5: =IF(Data!E51="x","✓","") | BB5: =IF(Data!E52="x","✓","") | BC5: =IF(Data!E53="x","✓","") | BD5: =IF(Data!E54="x","✓","") | BE5: =IF(Data!E55="x","✓","") | BF5: =IF(Data!E56="x","✓","") | BG5: =IF(Data!E57="x","✓","") | BH5: =IF(Data!E58="x","✓","") | BI5: =IF(Data!E59="x","✓","") | BJ5: =IF(Data!E60="x","✓","") | BK5: =IF(Data!E61="x","✓","")
B6: Ashland | C6: =COUNTIF(Data!F2:F61,"x") -> 6 | D6: =IF(Data!F2="x","✓","") | E6: =IF(Data!F3="x","✓","") | F6: =IF(Data!F4="x","✓","") | G6: =IF(Data!F5="x","✓","") | H6: =IF(Data!F6="x","✓","") | I6: =IF(Data!F7="x","✓","") | J6: =IF(Data!F8="x","✓","") | K6: =IF(Data!F9="x","✓","") | L6: =IF(Data!F10="x","✓","") | M6: =IF(Data!F11="x","✓","") | N6: =IF(Data!F12="x","✓","") | O6: =IF(Data!F13="x","✓","") | P6: =IF(Data!F14="x","✓","") | Q6: =IF(Data!F15="x","✓","") | R6: =IF(Data!F16="x","✓","") | S6: =IF(Data!F17="x","✓","") | T6: =IF(Data!F18="x","✓","") | U6: =IF(Data!F19="x","✓","") -> ✓ | V6: =IF(Data!F20="x","✓","") | W6: =IF(Data!F21="x","✓","") | X6: =IF(Data!F22="x","✓","") | Y6: =IF(Data!F23="x","✓","") | Z6: =IF(Data!F24="x","✓","") | AA6: =IF(Data!F25="x","✓","") | AB6: =IF(Data!F26="x","✓","") | AC6: =IF(Data!F27="x","✓","") | AD6: =IF(Data!F28="x","✓","") | AE6: =IF(Data!F29="x","✓","") -> ✓ | AF6: =IF(Data!F30="x","✓","") | AG6: =IF(Data!F31="x","✓","") | AH6: =IF(Data!F32="x","✓","") | AI6: =IF(Data!F33="x","✓","") | AJ6: =IF(Data!F34="x","✓","") | AK6: =IF(Data!F35="x","✓","") | AL6: =IF(Data!F36="x","✓","") -> ✓ | AM6: =IF(Data!F37="x","✓","") | AN6: =IF(Data!F38="x","✓","") -> ✓ | AO6: =IF(Data!F39="x","✓","") -> ✓ | AP6: =IF(Data!F40="x","✓","") | AQ6: =IF(Data!F41="x","✓","") | AR6: =IF(Data!F42="x","✓","") -> ✓ | AS6: =IF(Data!F43="x","✓","") | AT6: =IF(Data!F44="x","✓","") | AU6: =IF(Data!F45="x","✓","") | AV6: =IF(Data!F46="x","✓","") | AW6: =IF(Data!F47="x","✓","") | AX6: =IF(Data!F48="x","✓","") | AY6: =IF(Data!F49="x","✓","") | AZ6: =IF(Data!F50="x","✓","") | BA6: =IF(Data!F51="x","✓","") | BB6: =IF(Data!F52="x","✓","") | BC6: =IF(Data!F53="x","✓","") | BD6: =IF(Data!F54="x","✓","") | BE6: =IF(Data!F55="x","✓","") | BF6: =IF(Data!F56="x","✓","") | BG6: =IF(Data!F57="x","✓","") | BH6: =IF(Data!F58="x","✓","") | BI6: =IF(Data!F59="x","✓","") | BJ6: =IF(Data!F60="x","✓","") | BK6: =IF(Data!F61="x","✓","")
B7: Barron | C7: =COUNTIF(Data!G2:G61,"x") -> 6 | D7: =IF(Data!G2="x","✓","") | E7: =IF(Data!G3="x","✓","") | F7: =IF(Data!G4="x","✓","") | G7: =IF(Data!G5="x","✓","") | H7: =IF(Data!G6="x","✓","") | I7: =IF(Data!G7="x","✓","") | J7: =IF(Data!G8="x","✓","") | K7: =IF(Data!G9="x","✓","") | L7: =IF(Data!G10="x","✓","") | M7: =IF(Data!G11="x","✓","") | N7: =IF(Data!G12="x","✓","") | O7: =IF(Data!G13="x","✓","") | P7: =IF(Data!G14="x","✓","") | Q7: =IF(Data!G15="x","✓","") | R7: =IF(Data!G16="x","✓","") | S7: =IF(Data!G17="x","✓","") | T7: =IF(Data!G18="x","✓","") | U7: =IF(Data!G19="x","✓","") -> ✓ | V7: =IF(Data!G20="x","✓","") | W7: =IF(Data!G21="x","✓","") | X7: =IF(Data!G22="x","✓","") | Y7: =IF(Data!G23="x","✓","") | Z7: =IF(Data!G24="x","✓","") | AA7: =IF(Data!G25="x","✓","") | AB7: =IF(Data!G26="x","✓","") | AC7: =IF(Data!G27="x","✓","") | AD7: =IF(Data!G28="x","✓","") | AE7: =IF(Data!G29="x","✓","") -> ✓ | AF7: =IF(Data!G30="x","✓","") | AG7: =IF(Data!G31="x","✓","") | AH7: =IF(Data!G32="x","✓","") | AI7: =IF(Data!G33="x","✓","") | AJ7: =IF(Data!G34="x","✓","") | AK7: =IF(Data!G35="x","✓","") | AL7: =IF(Data!G36="x","✓","") -> ✓ | AM7: =IF(Data!G37="x","✓","") | AN7: =IF(Data!G38="x","✓","") -> ✓ | AO7: =IF(Data!G39="x","✓","") -> ✓ | AP7: =IF(Data!G40="x","✓","") | AQ7: =IF(Data!G41="x","✓","") | AR7: =IF(Data!G42="x","✓","") -> ✓ | AS7: =IF(Data!G43="x","✓","") | AT7: =IF(Data!G44="x","✓","") | AU7: =IF(Data!G45="x","✓","") | AV7: =IF(Data!G46="x","✓","") | AW7: =IF(Data!G47="x","✓","") | AX7: =IF(Data!G48="x","✓","") | AY7: =IF(Data!G49="x","✓","") | AZ7: =IF(Data!G50="x","✓","") | BA7: =IF(Data!G51="x","✓","") | BB7: =IF(Data!G52="x","✓","") | BC7: =IF(Data!G53="x","✓","") | BD7: =IF(Data!G54="x","✓","") | BE7: =IF(Data!G55="x","✓","") | BF7: =IF(Data!G56="x","✓","") | BG7: =IF(Data!G57="x","✓","") | BH7: =IF(Data!G58="x","✓","") | BI7: =IF(Data!G59="x","✓","") | BJ7: =IF(Data!G60="x","✓","") | BK7: =IF(Data!G61="x","✓","")
B8: Bayfield | C8: =COUNTIF(Data!H2:H61,"x") -> 6 | D8: =IF(Data!H2="x","✓","") | E8: =IF(Data!H3="x","✓","") | F8: =IF(Data!H4="x","✓","") | G8: =IF(Data!H5="x","✓","") | H8: =IF(Data!H6="x","✓","") | I8: =IF(Data!H7="x","✓","") | J8: =IF(Data!H8="x","✓","") | K8: =IF(Data!H9="x","✓","") | L8: =IF(Data!H10="x","✓","") | M8: =IF(Data!H11="x","✓","") | N8: =IF(Data!H12="x","✓","") | O8: =IF(Data!H13="x","✓","") | P8: =IF(Data!H14="x","✓","") | Q8: =IF(Data!H15="x","✓","") | R8: =IF(Data!H16="x","✓","") | S8: =IF(Data!H17="x","✓","") | T8: =IF(Data!H18="x","✓","") | U8: =IF(Data!H19="x","✓","") -> ✓ | V8: =IF(Data!H20="x","✓","") | W8: =IF(Data!H21="x","✓","") | X8: =IF(Data!H22="x","✓","") | Y8: =IF(Data!H23="x","✓","") | Z8: =IF(Data!H24="x","✓","") | AA8: =IF(Data!H25="x","✓","") | AB8: =IF(Data!H26="x","✓","") | AC8: =IF(Data!H27="x","✓","") | AD8: =IF(Data!H28="x","✓","") | AE8: =IF(Data!H29="x","✓","") -> ✓ | AF8: =IF(Data!H30="x","✓","") | AG8: =IF(Data!H31="x","✓","") | AH8: =IF(Data!H32="x","✓","") | AI8: =IF(Data!H33="x","✓","") | AJ8: =IF(Data!H34="x","✓","") | AK8: =IF(Data!H35="x","✓","") | AL8: =IF(Data!H36="x","✓","") -> ✓ | AM8: =IF(Data!H37="x","✓","") | AN8: =IF(Data!H38="x","✓","") -> ✓ | AO8: =IF(Data!H39="x","✓","") -> ✓ | AP8: =IF(Data!H40="x","✓","") | AQ8: =IF(Data!H41="x","✓","") | AR8: =IF(Data!H42="x","✓","") -> ✓ | AS8: =IF(Data!H43="x","✓","") | AT8: =IF(Data!H44="x","✓","") | AU8: =IF(Data!H45="x","✓","") | AV8: =IF(Data!H46="x","✓","") | AW8: =IF(Data!H47="x","✓","") | AX8: =IF(Data!H48="x","✓","") | AY8: =IF(Data!H49="x","✓","") | AZ8: =IF(Data!H50="x","✓","") | BA8: =IF(Data!H51="x","✓","") | BB8: =IF(Data!H52="x","✓","") | BC8: =IF(Data!H53="x","✓","") | BD8: =IF(Data!H54="x","✓","") | BE8: =IF(Data!H55="x","✓","") | BF8: =IF(Data!H56="x","✓","") | BG8: =IF(Data!H57="x","✓","") | BH8: =IF(Data!H58="x","✓","") | BI8: =IF(Data!H59="x","✓","") | BJ8: =IF(Data!H60="x","✓","") | BK8: =IF(Data!H61="x","✓","")
B9: Brown | C9: =COUNTIF(Data!I2:I61,"x") -> 5 | D9: =IF(Data!I2="x","✓","") | E9: =IF(Data!I3="x","✓","") | F9: =IF(Data!I4="x","✓","") | G9: =IF(Data!I5="x","✓","") | H9: =IF(Data!I6="x","✓","") | I9: =IF(Data!I7="x","✓","") | J9: =IF(Data!I8="x","✓","") | K9: =IF(Data!I9="x","✓","") | L9: =IF(Data!I10="x","✓","") | M9: =IF(Data!I11="x","✓","") | N9: =IF(Data!I12="x","✓","") | O9: =IF(Data!I13="x","✓","") | P9: =IF(Data!I14="x","✓","") | Q9: =IF(Data!I15="x","✓","") -> ✓ | R9: =IF(Data!I16="x","✓","") | S9: =IF(Data!I17="x","✓","") | T9: =IF(Data!I18="x","✓","") | U9: =IF(Data!I19="x","✓","") | V9: =IF(Data!I20="x","✓","") | W9: =IF(Data!I21="x","✓","") | X9: =IF(Data!I22="x","✓","") | Y9: =IF(Data!I23="x","✓","") | Z9: =IF(Data!I24="x","✓","") | AA9: =IF(Data!I25="x","✓","") | AB9: =IF(Data!I26="x","✓","") | AC9: =IF(Data!I27="x","✓","") | AD9: =IF(Data!I28="x","✓","") | AE9: =IF(Data!I29="x","✓","") | AF9: =IF(Data!I30="x","✓","") -> ✓ | AG9: =IF(Data!I31="x","✓","") | AH9: =IF(Data!I32="x","✓","") -> ✓ | AI9: =IF(Data!I33="x","✓","") | AJ9: =IF(Data!I34="x","✓","") | AK9: =IF(Data!I35="x","✓","") -> ✓ | AL9: =IF(Data!I36="x","✓","") | AM9: =IF(Data!I37="x","✓","") | AN9: =IF(Data!I38="x","✓","") | AO9: =IF(Data!I39="x","✓","") | AP9: =IF(Data!I40="x","✓","") | AQ9: =IF(Data!I41="x","✓","") | AR9: =IF(Data!I42="x","✓","") -> ✓ | AS9: =IF(Data!I43="x","✓","") | AT9: =IF(Data!I44="x","✓","") | AU9: =IF(Data!I45="x","✓","") | AV9: =IF(Data!I46="x","✓","") | AW9: =IF(Data!I47="x","✓","") | AX9: =IF(Data!I48="x","✓","") | AY9: =IF(Data!I49="x","✓","") | AZ9: =IF(Data!I50="x","✓","") | BA9: =IF(Data!I51="x","✓","") | BB9: =IF(Data!I52="x","✓","") | BC9: =IF(Data!I53="x","✓","") | BD9: =IF(Data!I54="x","✓","") | BE9: =IF(Data!I55="x","✓","") | BF9: =IF(Data!I56="x","✓","") | BG9: =IF(Data!I57="x","✓","") | BH9: =IF(Data!I58="x","✓","") | BI9: =IF(Data!I59="x","✓","") | BJ9: =IF(Data!I60="x","✓","") | BK9: =IF(Data!I61="x","✓","")
B10: Buffalo | C10: =COUNTIF(Data!J2:J61,"x") -> 8 | D10: =IF(Data!J2="x","✓","") | E10: =IF(Data!J3="x","✓","") | F10: =IF(Data!J4="x","✓","") | G10: =IF(Data!J5="x","✓","") | H10: =IF(Data!J6="x","✓","") | I10: =IF(Data!J7="x","✓","") | J10: =IF(Data!J8="x","✓","") | K10: =IF(Data!J9="x","✓","") | L10: =IF(Data!J10="x","✓","") | M10: =IF(Data!J11="x","✓","") | N10: =IF(Data!J12="x","✓","") | O10: =IF(Data!J13="x","✓","") | P10: =IF(Data!J14="x","✓","") | Q10: =IF(Data!J15="x","✓","") | R10: =IF(Data!J16="x","✓","") | S10: =IF(Data!J17="x","✓","") -> ✓ | T10: =IF(Data!J18="x","✓","") | U10: =IF(Data!J19="x","✓","") -> ✓ | V10: =IF(Data!J20="x","✓","") | W10: =IF(Data!J21="x","✓","") | X10: =IF(Data!J22="x","✓","") | Y10: =IF(Data!J23="x","✓","") | Z10: =IF(Data!J24="x","✓","") | AA10: =IF(Data!J25="x","✓","") | AB10: =IF(Data!J26="x","✓","") | AC10: =IF(Data!J27="x","✓","") -> ✓ | AD10: =IF(Data!J28="x","✓","") | AE10: =IF(Data!J29="x","✓","") | AF10: =IF(Data!J30="x","✓","") | AG10: =IF(Data!J31="x","✓","") | AH10: =IF(Data!J32="x","✓","") | AI10: =IF(Data!J33="x","✓","") -> ✓ | AJ10: =IF(Data!J34="x","✓","") | AK10: =IF(Data!J35="x","✓","") | AL10: =IF(Data!J36="x","✓","") -> ✓ | AM10: =IF(Data!J37="x","✓","") | AN10: =IF(Data!J38="x","✓","") -> ✓ | AO10: =IF(Data!J39="x","✓","") -> ✓ | AP10: =IF(Data!J40="x","✓","") | AQ10: =IF(Data!J41="x","✓","") | AR10: =IF(Data!J42="x","✓","") -> ✓ | AS10: =IF(Data!J43="x","✓","") | AT10: =IF(Data!J44="x","✓","") | AU10: =IF(Data!J45="x","✓","") | AV10: =IF(Data!J46="x","✓","") | AW10: =IF(Data!J47="x","✓","") | AX10: =IF(Data!J48="x","✓","") | AY10: =IF(Data!J49="x","✓","") | AZ10: =IF(Data!J50="x","✓","") | BA10: =IF(Data!J51="x","✓","") | BB10: =IF(Data!J52="x","✓","") | BC10: =IF(Data!J53="x","✓","") | BD10: =IF(Data!J54="x","✓","") | BE10: =IF(Data!J55="x","✓","") | BF10: =IF(Data!J56="x","✓","") | BG10: =IF(Data!J57="x","✓","") | BH10: =IF(Data!J58="x","✓","") | BI10: =IF(Data!J59="x","✓","") | BJ10: =IF(Data!J60="x","✓","") | BK10: =IF(Data!J61="x","✓","")
B11: Burnett | C11: =COUNTIF(Data!K2:K61,"x") -> 6 | D11: =IF(Data!K2="x","✓","") | E11: =IF(Data!K3="x","✓","") | F11: =IF(Data!K4="x","✓","") | G11: =IF(Data!K5="x","✓","") | H11: =IF(Data!K6="x","✓","") | I11: =IF(Data!K7="x","✓","") | J11: =IF(Data!K8="x","✓","") | K11: =IF(Data!K9="x","✓","") | L11: =IF(Data!K10="x","✓","") | M11: =IF(Data!K11="x","✓","") | N11: =IF(Data!K12="x","✓","") | O11: =IF(Data!K13="x","✓","") | P11: =IF(Data!K14="x","✓","") | Q11: =IF(Data!K15="x","✓","") | R11: =IF(Data!K16="x","✓","") | S11: =IF(Data!K17="x","✓","") | T11: =IF(Data!K18="x","✓","") | U11: =IF(Data!K19="x","✓","") -> ✓ | V11: =IF(Data!K20="x","✓","") | W11: =IF(Data!K21="x","✓","") | X11: =IF(Data!K22="x","✓","") | Y11: =IF(Data!K23="x","✓","") | Z11: =IF(Data!K24="x","✓","") | AA11: =IF(Data!K25="x","✓","") | AB11: =IF(Data!K26="x","✓","") | AC11: =IF(Data!K27="x","✓","") | AD11: =IF(Data!K28="x","✓","") | AE11: =IF(Data!K29="x","✓","") -> ✓ | AF11: =IF(Data!K30="x","✓","") | AG11: =IF(Data!K31="x","✓","") | AH11: =IF(Data!K32="x","✓","") | AI11: =IF(Data!K33="x","✓","") | AJ11: =IF(Data!K34="x","✓","") | AK11: =IF(Data!K35="x","✓","") | AL11: =IF(Data!K36="x","✓","") -> ✓ | AM11: =IF(Data!K37="x","✓","") | AN11: =IF(Data!K38="x","✓","") -> ✓ | AO11: =IF(Data!K39="x","✓","") -> ✓ | AP11: =IF(Data!K40="x","✓","") | AQ11: =IF(Data!K41="x","✓","") | AR11: =IF(Data!K42="x","✓","") -> ✓ | AS11: =IF(Data!K43="x","✓","") | AT11: =IF(Data!K44="x","✓","") | AU11: =IF(Data!K45="x","✓","") | AV11: =IF(Data!K46="x","✓","") | AW11: =IF(Data!K47="x","✓","") | AX11: =IF(Data!K48="x","✓","") | AY11: =IF(Data!K49="x","✓","") | AZ11: =IF(Data!K50="x","✓","") | BA11: =IF(Data!K51="x","✓","") | BB11: =IF(Data!K52="x","✓","") | BC11: =IF(Data!K53="x","✓","") | BD11: =IF(Data!K54="x","✓","") | BE11: =IF(Data!K55="x","✓","") | BF11: =IF(Data!K56="x","✓","") | BG11: =IF(Data!K57="x","✓","") | BH11: =IF(Data!K58="x","✓","") | BI11: =IF(Data!K59="x","✓","") | BJ11: =IF(Data!K60="x","✓","") | BK11: =IF(Data!K61="x","✓","")
B12: Calumet | C12: =COUNTIF(Data!L2:L61,"x") -> 5 | D12: =IF(Data!L2="x","✓","") | E12: =IF(Data!L3="x","✓","") | F12: =IF(Data!L4="x","✓","") | G12: =IF(Data!L5="x","✓","") | H12: =IF(Data!L6="x","✓","") | I12: =IF(Data!L7="x","✓","") | J12: =IF(Data!L8="x","✓","") | K12: =IF(Data!L9="x","✓","") | L12: =IF(Data!L10="x","✓","") | M12: =IF(Data!L11="x","✓","") | N12: =IF(Data!L12="x","✓","") | O12: =IF(Data!L13="x","✓","") | P12: =IF(Data!L14="x","✓","") | Q12: =IF(Data!L15="x","✓","") -> ✓ | R12: =IF(Data!L16="x","✓","") | S12: =IF(Data!L17="x","✓","") | T12: =IF(Data!L18="x","✓","") | U12: =IF(Data!L19="x","✓","") | V12: =IF(Data!L20="x","✓","") | W12: =IF(Data!L21="x","✓","") | X12: =IF(Data!L22="x","✓","") | Y12: =IF(Data!L23="x","✓","") | Z12: =IF(Data!L24="x","✓","") | AA12: =IF(Data!L25="x","✓","") | AB12: =IF(Data!L26="x","✓","") | AC12: =IF(Data!L27="x","✓","") | AD12: =IF(Data!L28="x","✓","") | AE12: =IF(Data!L29="x","✓","") | AF12: =IF(Data!L30="x","✓","") -> ✓ | AG12: =IF(Data!L31="x","✓","") | AH12: =IF(Data!L32="x","✓","") -> ✓ | AI12: =IF(Data!L33="x","✓","") | AJ12: =IF(Data!L34="x","✓","") | AK12: =IF(Data!L35="x","✓","") -> ✓ | AL12: =IF(Data!L36="x","✓","") | AM12: =IF(Data!L37="x","✓","") | AN12: =IF(Data!L38="x","✓","") | AO12: =IF(Data!L39="x","✓","") | AP12: =IF(Data!L40="x","✓","") | AQ12: =IF(Data!L41="x","✓","") | AR12: =IF(Data!L42="x","✓","") -> ✓ | AS12: =IF(Data!L43="x","✓","") | AT12: =IF(Data!L44="x","✓","") | AU12: =IF(Data!L45="x","✓","") | AV12: =IF(Data!L46="x","✓","") | AW12: =IF(Data!L47="x","✓","") | AX12: =IF(Data!L48="x","✓","") | AY12: =IF(Data!L49="x","✓","") | AZ12: =IF(Data!L50="x","✓","") | BA12: =IF(Data!L51="x","✓","") | BB12: =IF(Data!L52="x","✓","") | BC12: =IF(Data!L53="x","✓","") | BD12: =IF(Data!L54="x","✓","") | BE12: =IF(Data!L55="x","✓","") | BF12: =IF(Data!L56="x","✓","") | BG12: =IF(Data!L57="x","✓","") | BH12: =IF(Data!L58="x","✓","") | BI12: =IF(Data!L59="x","✓","") | BJ12: =IF(Data!L60="x","✓","") | BK12: =IF(Data!L61="x","✓","")
B13: Chippewa | C13: =COUNTIF(Data!M2:M61,"x") -> 7 | D13: =IF(Data!M2="x","✓","") | E13: =IF(Data!M3="x","✓","") | F13: =IF(Data!M4="x","✓","") | G13: =IF(Data!M5="x","✓","") | H13: =IF(Data!M6="x","✓","") | I13: =IF(Data!M7="x","✓","") | J13: =IF(Data!M8="x","✓","") | K13: =IF(Data!M9="x","✓","") | L13: =IF(Data!M10="x","✓","") | M13: =IF(Data!M11="x","✓","") | N13: =IF(Data!M12="x","✓","") | O13: =IF(Data!M13="x","✓","") | P13: =IF(Data!M14="x","✓","") | Q13: =IF(Data!M15="x","✓","") | R13: =IF(Data!M16="x","✓","") | S13: =IF(Data!M17="x","✓","") | T13: =IF(Data!M18="x","✓","") | U13: =IF(Data!M19="x","✓","") -> ✓ | V13: =IF(Data!M20="x","✓","") | W13: =IF(Data!M21="x","✓","") | X13: =IF(Data!M22="x","✓","") | Y13: =IF(Data!M23="x","✓","") | Z13: =IF(Data!M24="x","✓","") | AA13: =IF(Data!M25="x","✓","") | AB13: =IF(Data!M26="x","✓","") | AC13: =IF(Data!M27="x","✓","") | AD13: =IF(Data!M28="x","✓","") | AE13: =IF(Data!M29="x","✓","") -> ✓ | AF13: =IF(Data!M30="x","✓","") | AG13: =IF(Data!M31="x","✓","") | AH13: =IF(Data!M32="x","✓","") | AI13: =IF(Data!M33="x","✓","") -> ✓ | AJ13: =IF(Data!M34="x","✓","") | AK13: =IF(Data!M35="x","✓","") | AL13: =IF(Data!M36="x","✓","") -> ✓ | AM13: =IF(Data!M37="x","✓","") | AN13: =IF(Data!M38="x","✓","") -> ✓ | AO13: =IF(Data!M39="x","✓","") -> ✓ | AP13: =IF(Data!M40="x","✓","") | AQ13: =IF(Data!M41="x","✓","") | AR13: =IF(Data!M42="x","✓","") -> ✓ | AS13: =IF(Data!M43="x","✓","") | AT13: =IF(Data!M44="x","✓","") | AU13: =IF(Data!M45="x","✓","") | AV13: =IF(Data!M46="x","✓","") | AW13: =IF(Data!M47="x","✓","") | AX13: =IF(Data!M48="x","✓","") | AY13: =IF(Data!M49="x","✓","") | AZ13: =IF(Data!M50="x","✓","") | BA13: =IF(Data!M51="x","✓","") | BB13: =IF(Data!M52="x","✓","") | BC13: =IF(Data!M53="x","✓","") | BD13: =IF(Data!M54="x","✓","") | BE13: =IF(Data!M55="x","✓","") | BF13: =IF(Data!M56="x","✓","") | BG13: =IF(Data!M57="x","✓","") | BH13: =IF(Data!M58="x","✓","") | BI13: =IF(Data!M59="x","✓","") | BJ13: =IF(Data!M60="x","✓","") | BK13: =IF(Data!M61="x","✓","")
B14: Clark | C14: =COUNTIF(Data!N2:N61,"x") -> 7 | D14: =IF(Data!N2="x","✓","") | E14: =IF(Data!N3="x","✓","") | F14: =IF(Data!N4="x","✓","") | G14: =IF(Data!N5="x","✓","") | H14: =IF(Data!N6="x","✓","") | I14: =IF(Data!N7="x","✓","") | J14: =IF(Data!N8="x","✓","") | K14: =IF(Data!N9="x","✓","") | L14: =IF(Data!N10="x","✓","") | M14: =IF(Data!N11="x","✓","") | N14: =IF(Data!N12="x","✓","") | O14: =IF(Data!N13="x","✓","") | P14: =IF(Data!N14="x","✓","") | Q14: =IF(Data!N15="x","✓","") | R14: =IF(Data!N16="x","✓","") | S14: =IF(Data!N17="x","✓","") | T14: =IF(Data!N18="x","✓","") | U14: =IF(Data!N19="x","✓","") -> ✓ | V14: =IF(Data!N20="x","✓","") | W14: =IF(Data!N21="x","✓","") | X14: =IF(Data!N22="x","✓","") | Y14: =IF(Data!N23="x","✓","") | Z14: =IF(Data!N24="x","✓","") | AA14: =IF(Data!N25="x","✓","") | AB14: =IF(Data!N26="x","✓","") | AC14: =IF(Data!N27="x","✓","") | AD14: =IF(Data!N28="x","✓","") | AE14: =IF(Data!N29="x","✓","") -> ✓ | AF14: =IF(Data!N30="x","✓","") | AG14: =IF(Data!N31="x","✓","") | AH14: =IF(Data!N32="x","✓","") | AI14: =IF(Data!N33="x","✓","") -> ✓ | AJ14: =IF(Data!N34="x","✓","") | AK14: =IF(Data!N35="x","✓","") | AL14: =IF(Data!N36="x","✓","") -> ✓ | AM14: =IF(Data!N37="x","✓","") | AN14: =IF(Data!N38="x","✓","") -> ✓ | AO14: =IF(Data!N39="x","✓","") -> ✓ | AP14: =IF(Data!N40="x","✓","") | AQ14: =IF(Data!N41="x","✓","") | AR14: =IF(Data!N42="x","✓","") -> ✓ | AS14: =IF(Data!N43="x","✓","") | AT14: =IF(Data!N44="x","✓","") | AU14: =IF(Data!N45="x","✓","") | AV14: =IF(Data!N46="x","✓","") | AW14: =IF(Data!N47="x","✓","") | AX14: =IF(Data!N48="x","✓","") | AY14: =IF(Data!N49="x","✓","") | AZ14: =IF(Data!N50="x","✓","") | BA14: =IF(Data!N51="x","✓","") | BB14: =IF(Data!N52="x","✓","") | BC14: =IF(Data!N53="x","✓","") | BD14: =IF(Data!N54="x","✓","") | BE14: =IF(Data!N55="x","✓","") | BF14: =IF(Data!N56="x","✓","") | BG14: =IF(Data!N57="x","✓","") | BH14: =IF(Data!N58="x","✓","") | BI14: =IF(Data!N59="x","✓","") | BJ14: =IF(Data!N60="x","✓","") | BK14: =IF(Data!N61="x","✓","")
B15: Columbia | C15: =COUNTIF(Data!O2:O61,"x") -> 10 | D15: =IF(Data!O2="x","✓","") -> ✓ | E15: =IF(Data!O3="x","✓","") -> ✓ | F15: =IF(Data!O4="x","✓","") | G15: =IF(Data!O5="x","✓","") | H15: =IF(Data!O6="x","✓","") | I15: =IF(Data!O7="x","✓","") | J15: =IF(Data!O8="x","✓","") | K15: =IF(Data!O9="x","✓","") | L15: =IF(Data!O10="x","✓","") | M15: =IF(Data!O11="x","✓","") | N15: =IF(Data!O12="x","✓","") | O15: =IF(Data!O13="x","✓","") | P15: =IF(Data!O14="x","✓","") | Q15: =IF(Data!O15="x","✓","") | R15: =IF(Data!O16="x","✓","") | S15: =IF(Data!O17="x","✓","") | T15: =IF(Data!O18="x","✓","") | U15: =IF(Data!O19="x","✓","") | V15: =IF(Data!O20="x","✓","") -> ✓ | W15: =IF(Data!O21="x","✓","") -> ✓ | X15: =IF(Data!O22="x","✓","") | Y15: =IF(Data!O23="x","✓","") | Z15: =IF(Data!O24="x","✓","") | AA15: =IF(Data!O25="x","✓","") -> ✓ | AB15: =IF(Data!O26="x","✓","") -> ✓ | AC15: =IF(Data!O27="x","✓","") -> ✓ | AD15: =IF(Data!O28="x","✓","") | AE15: =IF(Data!O29="x","✓","") | AF15: =IF(Data!O30="x","✓","") | AG15: =IF(Data!O31="x","✓","") | AH15: =IF(Data!O32="x","✓","") | AI15: =IF(Data!O33="x","✓","") | AJ15: =IF(Data!O34="x","✓","") | AK15: =IF(Data!O35="x","✓","") | AL15: =IF(Data!O36="x","✓","") | AM15: =IF(Data!O37="x","✓","") -> ✓ | AN15: =IF(Data!O38="x","✓","") | AO15: =IF(Data!O39="x","✓","") | AP15: =IF(Data!O40="x","✓","") | AQ15: =IF(Data!O41="x","✓","") -> ✓ | AR15: =IF(Data!O42="x","✓","") -> ✓ | AS15: =IF(Data!O43="x","✓","") | AT15: =IF(Data!O44="x","✓","") | AU15: =IF(Data!O45="x","✓","") | AV15: =IF(Data!O46="x","✓","") | AW15: =IF(Data!O47="x","✓","") | AX15: =IF(Data!O48="x","✓","") | AY15: =IF(Data!O49="x","✓","") | AZ15: =IF(Data!O50="x","✓","") | BA15: =IF(Data!O51="x","✓","") | BB15: =IF(Data!O52="x","✓","") | BC15: =IF(Data!O53="x","✓","") | BD15: =IF(Data!O54="x","✓","") | BE15: =IF(Data!O55="x","✓","") | BF15: =IF(Data!O56="x","✓","") | BG15: =IF(Data!O57="x","✓","") | BH15: =IF(Data!O58="x","✓","") | BI15: =IF(Data!O59="x","✓","") | BJ15: =IF(Data!O60="x","✓","") | BK15: =IF(Data!O61="x","✓","")
B16: Crawford | C16: =COUNTIF(Data!P2:P61,"x") -> 12 | D16: =IF(Data!P2="x","✓","") -> ✓ | E16: =IF(Data!P3="x","✓","") -> ✓ | F16: =IF(Data!P4="x","✓","") | G16: =IF(Data!P5="x","✓","") | H16: =IF(Data!P6="x","✓","") | I16: =IF(Data!P7="x","✓","") | J16: =IF(Data!P8="x","✓","") | K16: =IF(Data!P9="x","✓","") | L16: =IF(Data!P10="x","✓","") | M16: =IF(Data!P11="x","✓","") | N16: =IF(Data!P12="x","✓","") -> ✓ | O16: =IF(Data!P13="x","✓","") | P16: =IF(Data!P14="x","✓","") | Q16: =IF(Data!P15="x","✓","") | R16: =IF(Data!P16="x","✓","") | S16: =IF(Data!P17="x","✓","") -> ✓ | T16: =IF(Data!P18="x","✓","") | U16: =IF(Data!P19="x","✓","") | V16: =IF(Data!P20="x","✓","") | W16: =IF(Data!P21="x","✓","") -> ✓ | X16: =IF(Data!P22="x","✓","") | Y16: =IF(Data!P23="x","✓","") | Z16: =IF(Data!P24="x","✓","") | AA16: =IF(Data!P25="x","✓","") -> ✓ | AB16: =IF(Data!P26="x","✓","") -> ✓ | AC16: =IF(Data!P27="x","✓","") -> ✓ | AD16: =IF(Data!P28="x","✓","") | AE16: =IF(Data!P29="x","✓","") | AF16: =IF(Data!P30="x","✓","") | AG16: =IF(Data!P31="x","✓","") | AH16: =IF(Data!P32="x","✓","") | AI16: =IF(Data!P33="x","✓","") -> ✓ | AJ16: =IF(Data!P34="x","✓","") | AK16: =IF(Data!P35="x","✓","") | AL16: =IF(Data!P36="x","✓","") | AM16: =IF(Data!P37="x","✓","") -> ✓ | AN16: =IF(Data!P38="x","✓","") | AO16: =IF(Data!P39="x","✓","") | AP16: =IF(Data!P40="x","✓","") | AQ16: =IF(Data!P41="x","✓","") -> ✓ | AR16: =IF(Data!P42="x","✓","") -> ✓ | AS16: =IF(Data!P43="x","✓","") | AT16: =IF(Data!P44="x","✓","") | AU16: =IF(Data!P45="x","✓","") | AV16: =IF(Data!P46="x","✓","") | AW16: =IF(Data!P47="x","✓","") | AX16: =IF(Data!P48="x","✓","") | AY16: =IF(Data!P49="x","✓","") | AZ16: =IF(Data!P50="x","✓","") | BA16: =IF(Data!P51="x","✓","") | BB16: =IF(Data!P52="x","✓","") | BC16: =IF(Data!P53="x","✓","") | BD16: =IF(Data!P54="x","✓","") | BE16: =IF(Data!P55="x","✓","") | BF16: =IF(Data!P56="x","✓","") | BG16: =IF(Data!P57="x","✓","") | BH16: =IF(Data!P58="x","✓","") | BI16: =IF(Data!P59="x","✓","") | BJ16: =IF(Data!P60="x","✓","") | BK16: =IF(Data!P61="x","✓","")
B17: Dane | C17: =COUNTIF(Data!Q2:Q61,"x") -> 16 | D17: =IF(Data!Q2="x","✓","") -> ✓ | E17: =IF(Data!Q3="x","✓","") -> ✓ | F17: =IF(Data!Q4="x","✓","") | G17: =IF(Data!Q5="x","✓","") | H17: =IF(Data!Q6="x","✓","") | I17: =IF(Data!Q7="x","✓","") | J17: =IF(Data!Q8="x","✓","") -> ✓ | K17: =IF(Data!Q9="x","✓","") -> ✓ | L17: =IF(Data!Q10="x","✓","") | M17: =IF(Data!Q11="x","✓","") | N17: =IF(Data!Q12="x","✓","") -> ✓ | O17: =IF(Data!Q13="x","✓","") -> ✓ | P17: =IF(Data!Q14="x","✓","") | Q17: =IF(Data!Q15="x","✓","") | R17: =IF(Data!Q16="x","✓","") | S17: =IF(Data!Q17="x","✓","") | T17: =IF(Data!Q18="x","✓","") | U17: =IF(Data!Q19="x","✓","") | V17: =IF(Data!Q20="x","✓","") -> ✓ | W17: =IF(Data!Q21="x","✓","") -> ✓ | X17: =IF(Data!Q22="x","✓","") -> ✓ | Y17: =IF(Data!Q23="x","✓","") -> ✓ | Z17: =IF(Data!Q24="x","✓","") | AA17: =IF(Data!Q25="x","✓","") -> ✓ | AB17: =IF(Data!Q26="x","✓","") -> ✓ | AC17: =IF(Data!Q27="x","✓","") -> ✓ | AD17: =IF(Data!Q28="x","✓","") | AE17: =IF(Data!Q29="x","✓","") | AF17: =IF(Data!Q30="x","✓","") | AG17: =IF(Data!Q31="x","✓","") | AH17: =IF(Data!Q32="x","✓","") | AI17: =IF(Data!Q33="x","✓","") | AJ17: =IF(Data!Q34="x","✓","") | AK17: =IF(Data!Q35="x","✓","") | AL17: =IF(Data!Q36="x","✓","") | AM17: =IF(Data!Q37="x","✓","") -> ✓ | AN17: =IF(Data!Q38="x","✓","") | AO17: =IF(Data!Q39="x","✓","") | AP17: =IF(Data!Q40="x","✓","") | AQ17: =IF(Data!Q41="x","✓","") -> ✓ | AR17: =IF(Data!Q42="x","✓","") -> ✓ | AS17: =IF(Data!Q43="x","✓","") | AT17: =IF(Data!Q44="x","✓","") | AU17: =IF(Data!Q45="x","✓","") | AV17: =IF(Data!Q46="x","✓","") | AW17: =IF(Data!Q47="x","✓","") | AX17: =IF(Data!Q48="x","✓","") | AY17: =IF(Data!Q49="x","✓","") | AZ17: =IF(Data!Q50="x","✓","") | BA17: =IF(Data!Q51="x","✓","") | BB17: =IF(Data!Q52="x","✓","") | BC17: =IF(Data!Q53="x","✓","") | BD17: =IF(Data!Q54="x","✓","") | BE17: =IF(Data!Q55="x","✓","") | BF17: =IF(Data!Q56="x","✓","") | BG17: =IF(Data!Q57="x","✓","") | BH17: =IF(Data!Q58="x","✓","") | BI17: =IF(Data!Q59="x","✓","") | BJ17: =IF(Data!Q60="x","✓","") | BK17: =IF(Data!Q61="x","✓","")
B18: Dodge | C18: =COUNTIF(Data!R2:R61,"x") -> 12 | D18: =IF(Data!R2="x","✓","") -> ✓ | E18: =IF(Data!R3="x","✓","") -> ✓ | F18: =IF(Data!R4="x","✓","") | G18: =IF(Data!R5="x","✓","") | H18: =IF(Data!R6="x","✓","") | I18: =IF(Data!R7="x","✓","") | J18: =IF(Data!R8="x","✓","") | K18: =IF(Data!R9="x","✓","") | L18: =IF(Data!R10="x","✓","") | M18: =IF(Data!R11="x","✓","") | N18: =IF(Data!R12="x","✓","") | O18: =IF(Data!R13="x","✓","") | P18: =IF(Data!R14="x","✓","") | Q18: =IF(Data!R15="x","✓","") | R18: =IF(Data!R16="x","✓","") | S18: =IF(Data!R17="x","✓","") | T18: =IF(Data!R18="x","✓","") | U18: =IF(Data!R19="x","✓","") | V18: =IF(Data!R20="x","✓","") -> ✓ | W18: =IF(Data!R21="x","✓","") -> ✓ | X18: =IF(Data!R22="x","✓","") | Y18: =IF(Data!R23="x","✓","") | Z18: =IF(Data!R24="x","✓","") | AA18: =IF(Data!R25="x","✓","") -> ✓ | AB18: =IF(Data!R26="x","✓","") -> ✓ | AC18: =IF(Data!R27="x","✓","") | AD18: =IF(Data!R28="x","✓","") -> ✓ | AE18: =IF(Data!R29="x","✓","") | AF18: =IF(Data!R30="x","✓","") | AG18: =IF(Data!R31="x","✓","") -> ✓ | AH18: =IF(Data!R32="x","✓","") | AI18: =IF(Data!R33="x","✓","") | AJ18: =IF(Data!R34="x","✓","") | AK18: =IF(Data!R35="x","✓","") -> ✓ | AL18: =IF(Data!R36="x","✓","") | AM18: =IF(Data!R37="x","✓","") -> ✓ | AN18: =IF(Data!R38="x","✓","") | AO18: =IF(Data!R39="x","✓","") | AP18: =IF(Data!R40="x","✓","") -> ✓ | AQ18: =IF(Data!R41="x","✓","") | AR18: =IF(Data!R42="x","✓","") -> ✓ | AS18: =IF(Data!R43="x","✓","") | AT18: =IF(Data!R44="x","✓","") | AU18: =IF(Data!R45="x","✓","") | AV18: =IF(Data!R46="x","✓","") | AW18: =IF(Data!R47="x","✓","") | AX18: =IF(Data!R48="x","✓","") | AY18: =IF(Data!R49="x","✓","") | AZ18: =IF(Data!R50="x","✓","") | BA18: =IF(Data!R51="x","✓","") | BB18: =IF(Data!R52="x","✓","") | BC18: =IF(Data!R53="x","✓","") | BD18: =IF(Data!R54="x","✓","") | BE18: =IF(Data!R55="x","✓","") | BF18: =IF(Data!R56="x","✓","") | BG18: =IF(Data!R57="x","✓","") | BH18: =IF(Data!R58="x","✓","") | BI18: =IF(Data!R59="x","✓","") | BJ18: =IF(Data!R60="x","✓","") | BK18: =IF(Data!R61="x","✓","")
B19: Door | C19: =COUNTIF(Data!S2:S61,"x") -> 5 | D19: =IF(Data!S2="x","✓","") | E19: =IF(Data!S3="x","✓","") | F19: =IF(Data!S4="x","✓","") | G19: =IF(Data!S5="x","✓","") | H19: =IF(Data!S6="x","✓","") | I19: =IF(Data!S7="x","✓","") | J19: =IF(Data!S8="x","✓","") | K19: =IF(Data!S9="x","✓","") | L19: =IF(Data!S10="x","✓","") | M19: =IF(Data!S11="x","✓","") | N19: =IF(Data!S12="x","✓","") | O19: =IF(Data!S13="x","✓","") | P19: =IF(Data!S14="x","✓","") | Q19: =IF(Data!S15="x","✓","") -> ✓ | R19: =IF(Data!S16="x","✓","") | S19: =IF(Data!S17="x","✓","") | T19: =IF(Data!S18="x","✓","") | U19: =IF(Data!S19="x","✓","") | V19: =IF(Data!S20="x","✓","") | W19: =IF(Data!S21="x","✓","") | X19: =IF(Data!S22="x","✓","") | Y19: =IF(Data!S23="x","✓","") | Z19: =IF(Data!S24="x","✓","") | AA19: =IF(Data!S25="x","✓","") | AB19: =IF(Data!S26="x","✓","") | AC19: =IF(Data!S27="x","✓","") | AD19: =IF(Data!S28="x","✓","") | AE19: =IF(Data!S29="x","✓","") | AF19: =IF(Data!S30="x","✓","") -> ✓ | AG19: =IF(Data!S31="x","✓","") | AH19: =IF(Data!S32="x","✓","") -> ✓ | AI19: =IF(Data!S33="x","✓","") | AJ19: =IF(Data!S34="x","✓","") | AK19: =IF(Data!S35="x","✓","") -> ✓ | AL19: =IF(Data!S36="x","✓","") | AM19: =IF(Data!S37="x","✓","") | AN19: =IF(Data!S38="x","✓","") | AO19: =IF(Data!S39="x","✓","") | AP19: =IF(Data!S40="x","✓","") | AQ19: =IF(Data!S41="x","✓","") | AR19: =IF(Data!S42="x","✓","") -> ✓ | AS19: =IF(Data!S43="x","✓","") | AT19: =IF(Data!S44="x","✓","") | AU19: =IF(Data!S45="x","✓","") | AV19: =IF(Data!S46="x","✓","") | AW19: =IF(Data!S47="x","✓","") | AX19: =IF(Data!S48="x","✓","") | AY19: =IF(Data!S49="x","✓","") | AZ19: =IF(Data!S50="x","✓","") | BA19: =IF(Data!S51="x","✓","") | BB19: =IF(Data!S52="x","✓","") | BC19: =IF(Data!S53="x","✓","") | BD19: =IF(Data!S54="x","✓","") | BE19: =IF(Data!S55="x","✓","") | BF19: =IF(Data!S56="x","✓","") | BG19: =IF(Data!S57="x","✓","") | BH19: =IF(Data!S58="x","✓","") | BI19: =IF(Data!S59="x","✓","") | BJ19: =IF(Data!S60="x","✓","") | BK19: =IF(Data!S61="x","✓","")
B20: Douglas | C20: =COUNTIF(Data!T2:T61,"x") -> 6 | D20: =IF(Data!T2="x","✓","") | E20: =IF(Data!T3="x","✓","") | F20: =IF(Data!T4="x","✓","") | G20: =IF(Data!T5="x","✓","") | H20: =IF(Data!T6="x","✓","") | I20: =IF(Data!T7="x","✓","") | J20: =IF(Data!T8="x","✓","") | K20: =IF(Data!T9="x","✓","") | L20: =IF(Data!T10="x","✓","") | M20: =IF(Data!T11="x","✓","") | N20: =IF(Data!T12="x","✓","") | O20: =IF(Data!T13="x","✓","") | P20: =IF(Data!T14="x","✓","") | Q20: =IF(Data!T15="x","✓","") | R20: =IF(Data!T16="x","✓","") | S20: =IF(Data!T17="x","✓","") | T20: =IF(Data!T18="x","✓","") | U20: =IF(Data!T19="x","✓","") -> ✓ | V20: =IF(Data!T20="x","✓","") | W20: =IF(Data!T21="x","✓","") | X20: =IF(Data!T22="x","✓","") | Y20: =IF(Data!T23="x","✓","") | Z20: =IF(Data!T24="x","✓","") | AA20: =IF(Data!T25="x","✓","") | AB20: =IF(Data!T26="x","✓","") | AC20: =IF(Data!T27="x","✓","") | AD20: =IF(Data!T28="x","✓","") | AE20: =IF(Data!T29="x","✓","") -> ✓ | AF20: =IF(Data!T30="x","✓","") | AG20: =IF(Data!T31="x","✓","") | AH20: =IF(Data!T32="x","✓","") | AI20: =IF(Data!T33="x","✓","") | AJ20: =IF(Data!T34="x","✓","") | AK20: =IF(Data!T35="x","✓","") | AL20: =IF(Data!T36="x","✓","") -> ✓ | AM20: =IF(Data!T37="x","✓","") | AN20: =IF(Data!T38="x","✓","") -> ✓ | AO20: =IF(Data!T39="x","✓","") -> ✓ | AP20: =IF(Data!T40="x","✓","") | AQ20: =IF(Data!T41="x","✓","") | AR20: =IF(Data!T42="x","✓","") -> ✓ | AS20: =IF(Data!T43="x","✓","") | AT20: =IF(Data!T44="x","✓","") | AU20: =IF(Data!T45="x","✓","") | AV20: =IF(Data!T46="x","✓","") | AW20: =IF(Data!T47="x","✓","") | AX20: =IF(Data!T48="x","✓","") | AY20: =IF(Data!T49="x","✓","") | AZ20: =IF(Data!T50="x","✓","") | BA20: =IF(Data!T51="x","✓","") | BB20: =IF(Data!T52="x","✓","") | BC20: =IF(Data!T53="x","✓","") | BD20: =IF(Data!T54="x","✓","") | BE20: =IF(Data!T55="x","✓","") | BF20: =IF(Data!T56="x","✓","") | BG20: =IF(Data!T57="x","✓","") | BH20: =IF(Data!T58="x","✓","") | BI20: =IF(Data!T59="x","✓","") | BJ20: =IF(Data!T60="x","✓","") | BK20: =IF(Data!T61="x","✓","")
B21: Dunn | C21: =COUNTIF(Data!U2:U61,"x") -> 7 | D21: =IF(Data!U2="x","✓","") | E21: =IF(Data!U3="x","✓","") | F21: =IF(Data!U4="x","✓","") | G21: =IF(Data!U5="x","✓","") | H21: =IF(Data!U6="x","✓","") | I21: =IF(Data!U7="x","✓","") | J21: =IF(Data!U8="x","✓","") | K21: =IF(Data!U9="x","✓","") | L21: =IF(Data!U10="x","✓","") | M21: =IF(Data!U11="x","✓","") | N21: =IF(Data!U12="x","✓","") | O21: =IF(Data!U13="x","✓","") | P21: =IF(Data!U14="x","✓","") | Q21: =IF(Data!U15="x","✓","") | R21: =IF(Data!U16="x","✓","") | S21: =IF(Data!U17="x","✓","") | T21: =IF(Data!U18="x","✓","") | U21: =IF(Data!U19="x","✓","") -> ✓ | V21: =IF(Data!U20="x","✓","") | W21: =IF(Data!U21="x","✓","") | X21: =IF(Data!U22="x","✓","") | Y21: =IF(Data!U23="x","✓","") | Z21: =IF(Data!U24="x","✓","") | AA21: =IF(Data!U25="x","✓","") | AB21: =IF(Data!U26="x","✓","") | AC21: =IF(Data!U27="x","✓","") | AD21: =IF(Data!U28="x","✓","") | AE21: =IF(Data!U29="x","✓","") -> ✓ | AF21: =IF(Data!U30="x","✓","") | AG21: =IF(Data!U31="x","✓","") | AH21: =IF(Data!U32="x","✓","") | AI21: =IF(Data!U33="x","✓","") -> ✓ | AJ21: =IF(Data!U34="x","✓","") | AK21: =IF(Data!U35="x","✓","") | AL21: =IF(Data!U36="x","✓","") -> ✓ | AM21: =IF(Data!U37="x","✓","") | AN21: =IF(Data!U38="x","✓","") -> ✓ | AO21: =IF(Data!U39="x","✓","") -> ✓ | AP21: =IF(Data!U40="x","✓","") | AQ21: =IF(Data!U41="x","✓","") | AR21: =IF(Data!U42="x","✓","") -> ✓ | AS21: =IF(Data!U43="x","✓","") | AT21: =IF(Data!U44="x","✓","") | AU21: =IF(Data!U45="x","✓","") | AV21: =IF(Data!U46="x","✓","") | AW21: =IF(Data!U47="x","✓","") | AX21: =IF(Data!U48="x","✓","") | AY21: =IF(Data!U49="x","✓","") | AZ21: =IF(Data!U50="x","✓","") | BA21: =IF(Data!U51="x","✓","") | BB21: =IF(Data!U52="x","✓","") | BC21: =IF(Data!U53="x","✓","") | BD21: =IF(Data!U54="x","✓","") | BE21: =IF(Data!U55="x","✓","") | BF21: =IF(Data!U56="x","✓","") | BG21: =IF(Data!U57="x","✓","") | BH21: =IF(Data!U58="x","✓","") | BI21: =IF(Data!U59="x","✓","") | BJ21: =IF(Data!U60="x","✓","") | BK21: =IF(Data!U61="x","✓","")
B22: Eau Claire | C22: =COUNTIF(Data!V2:V61,"x") -> 6 | D22: =IF(Data!V2="x","✓","") | E22: =IF(Data!V3="x","✓","") | F22: =IF(Data!V4="x","✓","") | G22: =IF(Data!V5="x","✓","") | H22: =IF(Data!V6="x","✓","") | I22: =IF(Data!V7="x","✓","") | J22: =IF(Data!V8="x","✓","") | K22: =IF(Data!V9="x","✓","") | L22: =IF(Data!V10="x","✓","") | M22: =IF(Data!V11="x","✓","") | N22: =IF(Data!V12="x","✓","") | O22: =IF(Data!V13="x","✓","") | P22: =IF(Data!V14="x","✓","") | Q22: =IF(Data!V15="x","✓","") | R22: =IF(Data!V16="x","✓","") | S22: =IF(Data!V17="x","✓","") | T22: =IF(Data!V18="x","✓","") | U22: =IF(Data!V19="x","✓","") | V22: =IF(Data!V20="x","✓","") | W22: =IF(Data!V21="x","✓","") | X22: =IF(Data!V22="x","✓","") | Y22: =IF(Data!V23="x","✓","") | Z22: =IF(Data!V24="x","✓","") | AA22: =IF(Data!V25="x","✓","") | AB22: =IF(Data!V26="x","✓","") | AC22: =IF(Data!V27="x","✓","") | AD22: =IF(Data!V28="x","✓","") | AE22: =IF(Data!V29="x","✓","") -> ✓ | AF22: =IF(Data!V30="x","✓","") | AG22: =IF(Data!V31="x","✓","") | AH22: =IF(Data!V32="x","✓","") | AI22: =IF(Data!V33="x","✓","") -> ✓ | AJ22: =IF(Data!V34="x","✓","") | AK22: =IF(Data!V35="x","✓","") | AL22: =IF(Data!V36="x","✓","") -> ✓ | AM22: =IF(Data!V37="x","✓","") | AN22: =IF(Data!V38="x","✓","") -> ✓ | AO22: =IF(Data!V39="x","✓","") -> ✓ | AP22: =IF(Data!V40="x","✓","") | AQ22: =IF(Data!V41="x","✓","") | AR22: =IF(Data!V42="x","✓","") -> ✓ | AS22: =IF(Data!V43="x","✓","") | AT22: =IF(Data!V44="x","✓","") | AU22: =IF(Data!V45="x","✓","") | AV22: =IF(Data!V46="x","✓","") | AW22: =IF(Data!V47="x","✓","") | AX22: =IF(Data!V48="x","✓","") | AY22: =IF(Data!V49="x","✓","") | AZ22: =IF(Data!V50="x","✓","") | BA22: =IF(Data!V51="x","✓","") | BB22: =IF(Data!V52="x","✓","") | BC22: =IF(Data!V53="x","✓","") | BD22: =IF(Data!V54="x","✓","") | BE22: =IF(Data!V55="x","✓","") | BF22: =IF(Data!V56="x","✓","") | BG22: =IF(Data!V57="x","✓","") | BH22: =IF(Data!V58="x","✓","") | BI22: =IF(Data!V59="x","✓","") | BJ22: =IF(Data!V60="x","✓","") | BK22: =IF(Data!V61="x","✓","")
B23: Florence | C23: =COUNTIF(Data!W2:W61,"x") -> 4 | D23: =IF(Data!W2="x","✓","") | E23: =IF(Data!W3="x","✓","") | F23: =IF(Data!W4="x","✓","") | G23: =IF(Data!W5="x","✓","") | H23: =IF(Data!W6="x","✓","") | I23: =IF(Data!W7="x","✓","") | J23: =IF(Data!W8="x","✓","") | K23: =IF(Data!W9="x","✓","") | L23: =IF(Data!W10="x","✓","") | M23: =IF(Data!W11="x","✓","") | N23: =IF(Data!W12="x","✓","") | O23: =IF(Data!W13="x","✓","") | P23: =IF(Data!W14="x","✓","") | Q23: =IF(Data!W15="x","✓","") | R23: =IF(Data!W16="x","✓","") | S23: =IF(Data!W17="x","✓","") | T23: =IF(Data!W18="x","✓","") | U23: =IF(Data!W19="x","✓","") | V23: =IF(Data!W20="x","✓","") | W23: =IF(Data!W21="x","✓","") | X23: =IF(Data!W22="x","✓","") | Y23: =IF(Data!W23="x","✓","") | Z23: =IF(Data!W24="x","✓","") | AA23: =IF(Data!W25="x","✓","") | AB23: =IF(Data!W26="x","✓","") | AC23: =IF(Data!W27="x","✓","") | AD23: =IF(Data!W28="x","✓","") | AE23: =IF(Data!W29="x","✓","") | AF23: =IF(Data!W30="x","✓","") -> ✓ | AG23: =IF(Data!W31="x","✓","") | AH23: =IF(Data!W32="x","✓","") -> ✓ | AI23: =IF(Data!W33="x","✓","") | AJ23: =IF(Data!W34="x","✓","") | AK23: =IF(Data!W35="x","✓","") | AL23: =IF(Data!W36="x","✓","") -> ✓ | AM23: =IF(Data!W37="x","✓","") | AN23: =IF(Data!W38="x","✓","") | AO23: =IF(Data!W39="x","✓","") | AP23: =IF(Data!W40="x","✓","") | AQ23: =IF(Data!W41="x","✓","") | AR23: =IF(Data!W42="x","✓","") -> ✓ | AS23: =IF(Data!W43="x","✓","") | AT23: =IF(Data!W44="x","✓","") | AU23: =IF(Data!W45="x","✓","") | AV23: =IF(Data!W46="x","✓","") | AW23: =IF(Data!W47="x","✓","") | AX23: =IF(Data!W48="x","✓","") | AY23: =IF(Data!W49="x","✓","") | AZ23: =IF(Data!W50="x","✓","") | BA23: =IF(Data!W51="x","✓","") | BB23: =IF(Data!W52="x","✓","") | BC23: =IF(Data!W53="x","✓","") | BD23: =IF(Data!W54="x","✓","") | BE23: =IF(Data!W55="x","✓","") | BF23: =IF(Data!W56="x","✓","") | BG23: =IF(Data!W57="x","✓","") | BH23: =IF(Data!W58="x","✓","") | BI23: =IF(Data!W59="x","✓","") | BJ23: =IF(Data!W60="x","✓","") | BK23: =IF(Data!W61="x","✓","")
B24: Fond du Lac | C24: =COUNTIF(Data!X2:X61,"x") -> 6 | D24: =IF(Data!X2="x","✓","") | E24: =IF(Data!X3="x","✓","") | F24: =IF(Data!X4="x","✓","") | G24: =IF(Data!X5="x","✓","") | H24: =IF(Data!X6="x","✓","") | I24: =IF(Data!X7="x","✓","") | J24: =IF(Data!X8="x","✓","") | K24: =IF(Data!X9="x","✓","") | L24: =IF(Data!X10="x","✓","") | M24: =IF(Data!X11="x","✓","") | N24: =IF(Data!X12="x","✓","") | O24: =IF(Data!X13="x","✓","") | P24: =IF(Data!X14="x","✓","") | Q24: =IF(Data!X15="x","✓","") -> ✓ | R24: =IF(Data!X16="x","✓","") | S24: =IF(Data!X17="x","✓","") | T24: =IF(Data!X18="x","✓","") | U24: =IF(Data!X19="x","✓","") | V24: =IF(Data!X20="x","✓","") | W24: =IF(Data!X21="x","✓","") | X24: =IF(Data!X22="x","✓","") | Y24: =IF(Data!X23="x","✓","") | Z24: =IF(Data!X24="x","✓","") | AA24: =IF(Data!X25="x","✓","") | AB24: =IF(Data!X26="x","✓","") | AC24: =IF(Data!X27="x","✓","") | AD24: =IF(Data!X28="x","✓","") | AE24: =IF(Data!X29="x","✓","") | AF24: =IF(Data!X30="x","✓","") -> ✓ | AG24: =IF(Data!X31="x","✓","") -> ✓ | AH24: =IF(Data!X32="x","✓","") | AI24: =IF(Data!X33="x","✓","") | AJ24: =IF(Data!X34="x","✓","") | AK24: =IF(Data!X35="x","✓","") -> ✓ | AL24: =IF(Data!X36="x","✓","") | AM24: =IF(Data!X37="x","✓","") | AN24: =IF(Data!X38="x","✓","") | AO24: =IF(Data!X39="x","✓","") | AP24: =IF(Data!X40="x","✓","") -> ✓ | AQ24: =IF(Data!X41="x","✓","") | AR24: =IF(Data!X42="x","✓","") -> ✓ | AS24: =IF(Data!X43="x","✓","") | AT24: =IF(Data!X44="x","✓","") | AU24: =IF(Data!X45="x","✓","") | AV24: =IF(Data!X46="x","✓","") | AW24: =IF(Data!X47="x","✓","") | AX24: =IF(Data!X48="x","✓","") | AY24: =IF(Data!X49="x","✓","") | AZ24: =IF(Data!X50="x","✓","") | BA24: =IF(Data!X51="x","✓","") | BB24: =IF(Data!X52="x","✓","") | BC24: =IF(Data!X53="x","✓","") | BD24: =IF(Data!X54="x","✓","") | BE24: =IF(Data!X55="x","✓","") | BF24: =IF(Data!X56="x","✓","") | BG24: =IF(Data!X57="x","✓","") | BH24: =IF(Data!X58="x","✓","") | BI24: =IF(Data!X59="x","✓","") | BJ24: =IF(Data!X60="x","✓","") | BK24: =IF(Data!X61="x","✓","")
B25: Forest | C25: =COUNTIF(Data!Y2:Y61,"x") -> 4 | D25: =IF(Data!Y2="x","✓","") | E25: =IF(Data!Y3="x","✓","") | F25: =IF(Data!Y4="x","✓","") | G25: =IF(Data!Y5="x","✓","") | H25: =IF(Data!Y6="x","✓","") | I25: =IF(Data!Y7="x","✓","") | J25: =IF(Data!Y8="x","✓","") | K25: =IF(Data!Y9="x","✓","") | L25: =IF(Data!Y10="x","✓","") | M25: =IF(Data!Y11="x","✓","") | N25: =IF(Data!Y12="x","✓","") | O25: =IF(Data!Y13="x","✓","") | P25: =IF(Data!Y14="x","✓","") | Q25: =IF(Data!Y15="x","✓","") | R25: =IF(Data!Y16="x","✓","") | S25: =IF(Data!Y17="x","✓","") | T25: =IF(Data!Y18="x","✓","") | U25: =IF(Data!Y19="x","✓","") | V25: =IF(Data!Y20="x","✓","") | W25: =IF(Data!Y21="x","✓","") | X25: =IF(Data!Y22="x","✓","") | Y25: =IF(Data!Y23="x","✓","") | Z25: =IF(Data!Y24="x","✓","") | AA25: =IF(Data!Y25="x","✓","") | AB25: =IF(Data!Y26="x","✓","") | AC25: =IF(Data!Y27="x","✓","") | AD25: =IF(Data!Y28="x","✓","") | AE25: =IF(Data!Y29="x","✓","") | AF25: =IF(Data!Y30="x","✓","") -> ✓ | AG25: =IF(Data!Y31="x","✓","") | AH25: =IF(Data!Y32="x","✓","") -> ✓ | AI25: =IF(Data!Y33="x","✓","") | AJ25: =IF(Data!Y34="x","✓","") | AK25: =IF(Data!Y35="x","✓","") | AL25: =IF(Data!Y36="x","✓","") -> ✓ | AM25: =IF(Data!Y37="x","✓","") | AN25: =IF(Data!Y38="x","✓","") | AO25: =IF(Data!Y39="x","✓","") | AP25: =IF(Data!Y40="x","✓","") | AQ25: =IF(Data!Y41="x","✓","") | AR25: =IF(Data!Y42="x","✓","") -> ✓ | AS25: =IF(Data!Y43="x","✓","") | AT25: =IF(Data!Y44="x","✓","") | AU25: =IF(Data!Y45="x","✓","") | AV25: =IF(Data!Y46="x","✓","") | AW25: =IF(Data!Y47="x","✓","") | AX25: =IF(Data!Y48="x","✓","") | AY25: =IF(Data!Y49="x","✓","") | AZ25: =IF(Data!Y50="x","✓","") | BA25: =IF(Data!Y51="x","✓","") | BB25: =IF(Data!Y52="x","✓","") | BC25: =IF(Data!Y53="x","✓","") | BD25: =IF(Data!Y54="x","✓","") | BE25: =IF(Data!Y55="x","✓","") | BF25: =IF(Data!Y56="x","✓","") | BG25: =IF(Data!Y57="x","✓","") | BH25: =IF(Data!Y58="x","✓","") | BI25: =IF(Data!Y59="x","✓","") | BJ25: =IF(Data!Y60="x","✓","") | BK25: =IF(Data!Y61="x","✓","")
